#usda 1.0
(
    customLayerData = {
        string creator = "MuJoCo USD Converter v0.1.0a6"
    }
    defaultPrim = "anymal_c"
    kilogramsPerUnit = 1
    metersPerUnit = 1
    upAxis = "Z"
)

def Xform "anymal_c"
{
    def Scope "Physics"
    {
        def Material "PhysicsMaterial" (
            prepend apiSchemas = ["PhysicsMaterialAPI", "NewtonMaterialAPI", "MjcMaterialAPI"]
        )
        {
            float newton:rollingFriction = 0.0001
            float newton:torsionalFriction = 0.005
            float physics:dynamicFriction = 1
        }

        def Material "PhysicsMaterial_1" (
            prepend apiSchemas = ["PhysicsMaterialAPI", "NewtonMaterialAPI", "MjcMaterialAPI"]
        )
        {
            uniform double mjc:rollingfriction = 0.01
            uniform double mjc:torsionalfriction = 0.02
            float newton:rollingFriction = 0.01
            float newton:torsionalFriction = 0.02
            float physics:dynamicFriction = 0.8
        }

        def MjcActuator "LF_HAA"
        {
            uniform double[] mjc:biasPrm = [0, -100, 0, 0, 0, 0, 0, 0, 0, 0]
            uniform token mjc:biasType = "affine"
            uniform double mjc:ctrlRange:max = 6.28
            uniform double mjc:ctrlRange:min = -6.28
            uniform double mjc:forceRange:max = 80
            uniform double mjc:forceRange:min = -80
            uniform double[] mjc:gainPrm = [100, 0, 0, 0, 0, 0, 0, 0, 0, 0]
            rel mjc:target = </anymal_c/Geometry/base/LF_HIP/LF_HAA>
        }

        def MjcActuator "LF_HFE"
        {
            uniform double[] mjc:biasPrm = [0, -100, 0, 0, 0, 0, 0, 0, 0, 0]
            uniform token mjc:biasType = "affine"
            uniform double mjc:ctrlRange:max = 6.28
            uniform double mjc:ctrlRange:min = -6.28
            uniform double mjc:forceRange:max = 80
            uniform double mjc:forceRange:min = -80
            uniform double[] mjc:gainPrm = [100, 0, 0, 0, 0, 0, 0, 0, 0, 0]
            rel mjc:target = </anymal_c/Geometry/base/LF_HIP/LF_THIGH/LF_HFE>
        }

        def MjcActuator "LF_KFE"
        {
            uniform double[] mjc:biasPrm = [0, -100, 0, 0, 0, 0, 0, 0, 0, 0]
            uniform token mjc:biasType = "affine"
            uniform double mjc:ctrlRange:max = 6.28
            uniform double mjc:ctrlRange:min = -6.28
            uniform double mjc:forceRange:max = 80
            uniform double mjc:forceRange:min = -80
            uniform double[] mjc:gainPrm = [100, 0, 0, 0, 0, 0, 0, 0, 0, 0]
            rel mjc:target = </anymal_c/Geometry/base/LF_HIP/LF_THIGH/LF_SHANK/LF_KFE>
        }

        def MjcActuator "RF_HAA"
        {
            uniform double[] mjc:biasPrm = [0, -100, 0, 0, 0, 0, 0, 0, 0, 0]
            uniform token mjc:biasType = "affine"
            uniform double mjc:ctrlRange:max = 6.28
            uniform double mjc:ctrlRange:min = -6.28
            uniform double mjc:forceRange:max = 80
            uniform double mjc:forceRange:min = -80
            uniform double[] mjc:gainPrm = [100, 0, 0, 0, 0, 0, 0, 0, 0, 0]
            rel mjc:target = </anymal_c/Geometry/base/RF_HIP/RF_HAA>
        }

        def MjcActuator "RF_HFE"
        {
            uniform double[] mjc:biasPrm = [0, -100, 0, 0, 0, 0, 0, 0, 0, 0]
            uniform token mjc:biasType = "affine"
            uniform double mjc:ctrlRange:max = 6.28
            uniform double mjc:ctrlRange:min = -6.28
            uniform double mjc:forceRange:max = 80
            uniform double mjc:forceRange:min = -80
            uniform double[] mjc:gainPrm = [100, 0, 0, 0, 0, 0, 0, 0, 0, 0]
            rel mjc:target = </anymal_c/Geometry/base/RF_HIP/RF_THIGH/RF_HFE>
        }

        def MjcActuator "RF_KFE"
        {
            uniform double[] mjc:biasPrm = [0, -100, 0, 0, 0, 0, 0, 0, 0, 0]
            uniform token mjc:biasType = "affine"
            uniform double mjc:ctrlRange:max = 6.28
            uniform double mjc:ctrlRange:min = -6.28
            uniform double mjc:forceRange:max = 80
            uniform double mjc:forceRange:min = -80
            uniform double[] mjc:gainPrm = [100, 0, 0, 0, 0, 0, 0, 0, 0, 0]
            rel mjc:target = </anymal_c/Geometry/base/RF_HIP/RF_THIGH/RF_SHANK/RF_KFE>
        }

        def MjcActuator "LH_HAA"
        {
            uniform double[] mjc:biasPrm = [0, -100, 0, 0, 0, 0, 0, 0, 0, 0]
            uniform token mjc:biasType = "affine"
            uniform double mjc:ctrlRange:max = 6.28
            uniform double mjc:ctrlRange:min = -6.28
            uniform double mjc:forceRange:max = 80
            uniform double mjc:forceRange:min = -80
            uniform double[] mjc:gainPrm = [100, 0, 0, 0, 0, 0, 0, 0, 0, 0]
            rel mjc:target = </anymal_c/Geometry/base/LH_HIP/LH_HAA>
        }

        def MjcActuator "LH_HFE"
        {
            uniform double[] mjc:biasPrm = [0, -100, 0, 0, 0, 0, 0, 0, 0, 0]
            uniform token mjc:biasType = "affine"
            uniform double mjc:ctrlRange:max = 6.28
            uniform double mjc:ctrlRange:min = -6.28
            uniform double mjc:forceRange:max = 80
            uniform double mjc:forceRange:min = -80
            uniform double[] mjc:gainPrm = [100, 0, 0, 0, 0, 0, 0, 0, 0, 0]
            rel mjc:target = </anymal_c/Geometry/base/LH_HIP/LH_THIGH/LH_HFE>
        }

        def MjcActuator "LH_KFE"
        {
            uniform double[] mjc:biasPrm = [0, -100, 0, 0, 0, 0, 0, 0, 0, 0]
            uniform token mjc:biasType = "affine"
            uniform double mjc:ctrlRange:max = 6.28
            uniform double mjc:ctrlRange:min = -6.28
            uniform double mjc:forceRange:max = 80
            uniform double mjc:forceRange:min = -80
            uniform double[] mjc:gainPrm = [100, 0, 0, 0, 0, 0, 0, 0, 0, 0]
            rel mjc:target = </anymal_c/Geometry/base/LH_HIP/LH_THIGH/LH_SHANK/LH_KFE>
        }

        def MjcActuator "RH_HAA"
        {
            uniform double[] mjc:biasPrm = [0, -100, 0, 0, 0, 0, 0, 0, 0, 0]
            uniform token mjc:biasType = "affine"
            uniform double mjc:ctrlRange:max = 6.28
            uniform double mjc:ctrlRange:min = -6.28
            uniform double mjc:forceRange:max = 80
            uniform double mjc:forceRange:min = -80
            uniform double[] mjc:gainPrm = [100, 0, 0, 0, 0, 0, 0, 0, 0, 0]
            rel mjc:target = </anymal_c/Geometry/base/RH_HIP/RH_HAA>
        }

        def MjcActuator "RH_HFE"
        {
            uniform double[] mjc:biasPrm = [0, -100, 0, 0, 0, 0, 0, 0, 0, 0]
            uniform token mjc:biasType = "affine"
            uniform double mjc:ctrlRange:max = 6.28
            uniform double mjc:ctrlRange:min = -6.28
            uniform double mjc:forceRange:max = 80
            uniform double mjc:forceRange:min = -80
            uniform double[] mjc:gainPrm = [100, 0, 0, 0, 0, 0, 0, 0, 0, 0]
            rel mjc:target = </anymal_c/Geometry/base/RH_HIP/RH_THIGH/RH_HFE>
        }

        def MjcActuator "RH_KFE"
        {
            uniform double[] mjc:biasPrm = [0, -100, 0, 0, 0, 0, 0, 0, 0, 0]
            uniform token mjc:biasType = "affine"
            uniform double mjc:ctrlRange:max = 6.28
            uniform double mjc:ctrlRange:min = -6.28
            uniform double mjc:forceRange:max = 80
            uniform double mjc:forceRange:min = -80
            uniform double[] mjc:gainPrm = [100, 0, 0, 0, 0, 0, 0, 0, 0, 0]
            rel mjc:target = </anymal_c/Geometry/base/RH_HIP/RH_THIGH/RH_SHANK/RH_KFE>
        }
    }

    def "Geometry"
    {
        def "base" (
            prepend apiSchemas = ["PhysicsRigidBodyAPI", "PhysicsMassAPI", "PhysicsArticulationRootAPI", "NewtonArticulationRootAPI"]
        )
        {
            point3f physics:centerOfMass = (0.0025, 0, 0.0502071)
            float3 physics:diagonalInertia = (0.639559, 0.624031, 0.217374)
            float physics:mass = 19.2035
            quatf physics:principalAxes = (0.5, 0.5, 0.5, 0.5)

            over "Box" (
                prepend apiSchemas = ["PhysicsCollisionAPI", "NewtonCollisionAPI", "MjcCollisionAPI", "PhysicsMassAPI", "MaterialBindingAPI"]
            )
            {
                rel material:binding:physics = </anymal_c/Physics/PhysicsMaterial>
                uniform int mjc:group = 3
                float newton:contactGap = 0
                float physics:density = 1000
            }

            over "Cylinder" (
                prepend apiSchemas = ["PhysicsCollisionAPI", "NewtonCollisionAPI", "MjcCollisionAPI", "PhysicsMassAPI", "MaterialBindingAPI"]
            )
            {
                rel material:binding:physics = </anymal_c/Physics/PhysicsMaterial>
                uniform int mjc:group = 3
                float newton:contactGap = 0
                float physics:density = 1000
            }

            over "Cylinder_1" (
                prepend apiSchemas = ["PhysicsCollisionAPI", "NewtonCollisionAPI", "MjcCollisionAPI", "PhysicsMassAPI", "MaterialBindingAPI"]
            )
            {
                rel material:binding:physics = </anymal_c/Physics/PhysicsMaterial>
                uniform int mjc:group = 3
                float newton:contactGap = 0
                float physics:density = 1000
            }

            over "Cylinder_2" (
                prepend apiSchemas = ["PhysicsCollisionAPI", "NewtonCollisionAPI", "MjcCollisionAPI", "PhysicsMassAPI", "MaterialBindingAPI"]
            )
            {
                rel material:binding:physics = </anymal_c/Physics/PhysicsMaterial>
                uniform int mjc:group = 3
                float newton:contactGap = 0
                float physics:density = 1000
            }

            over "Cylinder_3" (
                prepend apiSchemas = ["PhysicsCollisionAPI", "NewtonCollisionAPI", "MjcCollisionAPI", "PhysicsMassAPI", "MaterialBindingAPI"]
            )
            {
                rel material:binding:physics = </anymal_c/Physics/PhysicsMaterial>
                uniform int mjc:group = 3
                float newton:contactGap = 0
                float physics:density = 1000
            }

            over "Box_1" (
                prepend apiSchemas = ["PhysicsCollisionAPI", "NewtonCollisionAPI", "MjcCollisionAPI", "PhysicsMassAPI", "MaterialBindingAPI"]
            )
            {
                rel material:binding:physics = </anymal_c/Physics/PhysicsMaterial>
                uniform int mjc:group = 3
                float newton:contactGap = 0
                float physics:density = 1000
            }

            over "Cylinder_4" (
                prepend apiSchemas = ["PhysicsCollisionAPI", "NewtonCollisionAPI", "MjcCollisionAPI", "PhysicsMassAPI", "MaterialBindingAPI"]
            )
            {
                rel material:binding:physics = </anymal_c/Physics/PhysicsMaterial>
                uniform int mjc:group = 3
                float newton:contactGap = 0
                float physics:density = 1000
            }

            over "Cylinder_5" (
                prepend apiSchemas = ["PhysicsCollisionAPI", "NewtonCollisionAPI", "MjcCollisionAPI", "PhysicsMassAPI", "MaterialBindingAPI"]
            )
            {
                rel material:binding:physics = </anymal_c/Physics/PhysicsMaterial>
                uniform int mjc:group = 3
                float newton:contactGap = 0
                float physics:density = 1000
            }

            over "Box_2" (
                prepend apiSchemas = ["PhysicsCollisionAPI", "NewtonCollisionAPI", "MjcCollisionAPI", "PhysicsMassAPI", "MaterialBindingAPI"]
            )
            {
                rel material:binding:physics = </anymal_c/Physics/PhysicsMaterial>
                uniform int mjc:group = 3
                float newton:contactGap = 0
                float physics:density = 1000
            }

            over "Cylinder_6" (
                prepend apiSchemas = ["PhysicsCollisionAPI", "NewtonCollisionAPI", "MjcCollisionAPI", "PhysicsMassAPI", "MaterialBindingAPI"]
            )
            {
                rel material:binding:physics = </anymal_c/Physics/PhysicsMaterial>
                uniform int mjc:group = 3
                float newton:contactGap = 0
                float physics:density = 1000
            }

            over "Cylinder_7" (
                prepend apiSchemas = ["PhysicsCollisionAPI", "NewtonCollisionAPI", "MjcCollisionAPI", "PhysicsMassAPI", "MaterialBindingAPI"]
            )
            {
                rel material:binding:physics = </anymal_c/Physics/PhysicsMaterial>
                uniform int mjc:group = 3
                float newton:contactGap = 0
                float physics:density = 1000
            }

            over "Cylinder_8" (
                prepend apiSchemas = ["PhysicsCollisionAPI", "NewtonCollisionAPI", "MjcCollisionAPI", "PhysicsMassAPI", "MaterialBindingAPI"]
            )
            {
                rel material:binding:physics = </anymal_c/Physics/PhysicsMaterial>
                uniform int mjc:group = 3
                float newton:contactGap = 0
                float physics:density = 1000
            }

            def "LF_HIP" (
                prepend apiSchemas = ["PhysicsRigidBodyAPI", "PhysicsMassAPI"]
            )
            {
                point3f physics:centerOfMass = (0.0566606, -0.015294, -0.00829784)
                float3 physics:diagonalInertia = (0.00585729, 0.00491868, 0.00329081)
                float physics:mass = 2.781
                quatf physics:principalAxes = (-0.127978, 0.709783, -0.135278, 0.679359)

                over "Cylinder" (
                    prepend apiSchemas = ["PhysicsCollisionAPI", "NewtonCollisionAPI", "MjcCollisionAPI", "PhysicsMassAPI", "MaterialBindingAPI"]
                )
                {
                    rel material:binding:physics = </anymal_c/Physics/PhysicsMaterial>
                    uniform int mjc:group = 3
                    float newton:contactGap = 0
                    float physics:density = 1000
                }

                def PhysicsRevoluteJoint "LF_HAA" (
                    prepend apiSchemas = ["MjcJointAPI"]
                )
                {
                    uniform double mjc:damping = 1
                    uniform double mjc:frictionloss = 0.1
                    uniform token physics:axis = "X"
                    rel physics:body0 = </anymal_c/Geometry/base>
                    rel physics:body1 = </anymal_c/Geometry/base/LF_HIP>
                    point3f physics:localPos0 = (0.2999, 0.104, 0)
                    point3f physics:localPos1 = (0, 0, 0)
                    quatf physics:localRot0 = (0.25881898, 0.9659259, 0, -4.5384247e-17)
                    quatf physics:localRot1 = (1, 0, 0, 0)
                    float physics:lowerLimit = -41.25296
                    float physics:upperLimit = 28.074932
                }

                def "LF_THIGH" (
                    prepend apiSchemas = ["PhysicsRigidBodyAPI", "PhysicsMassAPI"]
                )
                {
                    point3f physics:centerOfMass = (0.0308147, 0.0000464995, -0.245696)
                    float3 physics:diagonalInertia = (0.03025, 0.0298943, 0.00418465)
                    float physics:mass = 3.071
                    quatf physics:principalAxes = (0.993166, -0.00515309, -0.0806592, 0.0841972)

                    over "Cylinder" (
                        prepend apiSchemas = ["PhysicsCollisionAPI", "NewtonCollisionAPI", "MjcCollisionAPI", "PhysicsMassAPI", "MaterialBindingAPI"]
                    )
                    {
                        rel material:binding:physics = </anymal_c/Physics/PhysicsMaterial>
                        uniform int mjc:group = 3
                        float newton:contactGap = 0
                        float physics:density = 1000
                    }

                    over "Box" (
                        prepend apiSchemas = ["PhysicsCollisionAPI", "NewtonCollisionAPI", "MjcCollisionAPI", "PhysicsMassAPI", "MaterialBindingAPI"]
                    )
                    {
                        rel material:binding:physics = </anymal_c/Physics/PhysicsMaterial>
                        uniform int mjc:group = 3
                        float newton:contactGap = 0
                        float physics:density = 1000
                    }

                    over "Cylinder_1" (
                        prepend apiSchemas = ["PhysicsCollisionAPI", "NewtonCollisionAPI", "MjcCollisionAPI", "PhysicsMassAPI", "MaterialBindingAPI"]
                    )
                    {
                        rel material:binding:physics = </anymal_c/Physics/PhysicsMaterial>
                        uniform int mjc:group = 3
                        float newton:contactGap = 0
                        float physics:density = 1000
                    }

                    def PhysicsRevoluteJoint "LF_HFE" (
                        prepend apiSchemas = ["MjcJointAPI"]
                    )
                    {
                        uniform double mjc:damping = 1
                        uniform double mjc:frictionloss = 0.1
                        uniform token physics:axis = "X"
                        rel physics:body0 = </anymal_c/Geometry/base/LF_HIP>
                        rel physics:body1 = </anymal_c/Geometry/base/LF_HIP/LF_THIGH>
                        point3f physics:localPos0 = (0.0599, -0.0725816, -0.041905)
                        point3f physics:localPos1 = (0, 0, 0)
                        quatf physics:localRot0 = (0.18301292, -0.68301266, 0.68301266, 0.1830129)
                        quatf physics:localRot1 = (1, 0, 0, 0)
                        float physics:lowerLimit = -540.0001
                        float physics:upperLimit = 540.0001
                    }

                    def "LF_SHANK" (
                        prepend apiSchemas = ["PhysicsRigidBodyAPI", "PhysicsMassAPI"]
                    )
                    {
                        point3f physics:centerOfMass = (0.005462, -0.0612528, -0.0806598)
                        float3 physics:diagonalInertia = (0.0101637, 0.00923838, 0.00111927)
                        float physics:mass = 0.58842
                        quatf physics:principalAxes = (0.992934, -0.115904, -0.00105487, -0.0254421)

                        over "Cylinder" (
                            prepend apiSchemas = ["PhysicsCollisionAPI", "NewtonCollisionAPI", "MjcCollisionAPI", "PhysicsMassAPI", "MaterialBindingAPI"]
                        )
                        {
                            rel material:binding:physics = </anymal_c/Physics/PhysicsMaterial>
                            uniform int mjc:group = 3
                            float newton:contactGap = 0
                            float physics:density = 1000
                        }

                        over "Box" (
                            prepend apiSchemas = ["PhysicsCollisionAPI", "NewtonCollisionAPI", "MjcCollisionAPI", "PhysicsMassAPI", "MaterialBindingAPI"]
                        )
                        {
                            rel material:binding:physics = </anymal_c/Physics/PhysicsMaterial>
                            uniform int mjc:group = 3
                            float newton:contactGap = 0
                            float physics:density = 1000
                        }

                        over "Cylinder_1" (
                            prepend apiSchemas = ["PhysicsCollisionAPI", "NewtonCollisionAPI", "MjcCollisionAPI", "PhysicsMassAPI", "MaterialBindingAPI"]
                        )
                        {
                            rel material:binding:physics = </anymal_c/Physics/PhysicsMaterial>
                            uniform int mjc:group = 3
                            float newton:contactGap = 0
                            float physics:density = 1000
                        }

                        over "Sphere" (
                            prepend apiSchemas = ["PhysicsCollisionAPI", "NewtonCollisionAPI", "MjcCollisionAPI", "PhysicsMassAPI", "MaterialBindingAPI"]
                        )
                        {
                            rel material:binding:physics = </anymal_c/Physics/PhysicsMaterial_1>
                            uniform int mjc:condim = 6
                            uniform int mjc:group = 3
                            uniform int mjc:priority = 1
                            uniform double[] mjc:solimp = [0.015, 1, 0.03, 0.5, 2]
                            float newton:contactGap = 0
                            float physics:density = 1000
                        }

                        def PhysicsRevoluteJoint "LF_KFE" (
                            prepend apiSchemas = ["MjcJointAPI"]
                        )
                        {
                            uniform double mjc:damping = 1
                            uniform double mjc:frictionloss = 0.1
                            uniform token physics:axis = "X"
                            rel physics:body0 = </anymal_c/Geometry/base/LF_HIP/LF_THIGH>
                            rel physics:body1 = </anymal_c/Geometry/base/LF_HIP/LF_THIGH/LF_SHANK>
                            point3f physics:localPos0 = (0.1003, 0, -0.285)
                            point3f physics:localPos1 = (0, 0, 0)
                            quatf physics:localRot0 = (1, 0, 0, 0)
                            quatf physics:localRot1 = (1, 0, 0, 0)
                            float physics:lowerLimit = -540.0001
                            float physics:upperLimit = 540.0001
                        }
                    }
                }
            }

            def "RF_HIP" (
                prepend apiSchemas = ["PhysicsRigidBodyAPI", "PhysicsMassAPI"]
            )
            {
                point3f physics:centerOfMass = (0.0567633, 0.015294, -0.00829784)
                float3 physics:diagonalInertia = (0.00585928, 0.0049205, 0.00329064)
                float physics:mass = 2.781
                quatf physics:principalAxes = (0.13524, 0.679072, 0.127985, 0.710065)

                over "Cylinder" (
                    prepend apiSchemas = ["PhysicsCollisionAPI", "NewtonCollisionAPI", "MjcCollisionAPI", "PhysicsMassAPI", "MaterialBindingAPI"]
                )
                {
                    rel material:binding:physics = </anymal_c/Physics/PhysicsMaterial>
                    uniform int mjc:group = 3
                    float newton:contactGap = 0
                    float physics:density = 1000
                }

                def PhysicsRevoluteJoint "RF_HAA" (
                    prepend apiSchemas = ["MjcJointAPI"]
                )
                {
                    uniform double mjc:damping = 1
                    uniform double mjc:frictionloss = 0.1
                    uniform token physics:axis = "X"
                    rel physics:body0 = </anymal_c/Geometry/base>
                    rel physics:body1 = </anymal_c/Geometry/base/RF_HIP>
                    point3f physics:localPos0 = (0.2999, -0.104, 0)
                    point3f physics:localPos1 = (0, 0, 0)
                    quatf physics:localRot0 = (-0.25881898, 0.9659259, 0, -7.7080435e-17)
                    quatf physics:localRot1 = (1, 0, 0, 0)
                    float physics:lowerLimit = -28.074932
                    float physics:upperLimit = 41.25296
                }

                def "RF_THIGH" (
                    prepend apiSchemas = ["PhysicsRigidBodyAPI", "PhysicsMassAPI"]
                )
                {
                    point3f physics:centerOfMass = (0.0308147, 0.0000464995, -0.245696)
                    float3 physics:diagonalInertia = (0.0302511, 0.0298933, 0.0041845)
                    float physics:mass = 3.071
                    quatf physics:principalAxes = (0.992775, -0.00512735, -0.0806685, 0.0886811)

                    over "Cylinder" (
                        prepend apiSchemas = ["PhysicsCollisionAPI", "NewtonCollisionAPI", "MjcCollisionAPI", "PhysicsMassAPI", "MaterialBindingAPI"]
                    )
                    {
                        rel material:binding:physics = </anymal_c/Physics/PhysicsMaterial>
                        uniform int mjc:group = 3
                        float newton:contactGap = 0
                        float physics:density = 1000
                    }

                    over "Box" (
                        prepend apiSchemas = ["PhysicsCollisionAPI", "NewtonCollisionAPI", "MjcCollisionAPI", "PhysicsMassAPI", "MaterialBindingAPI"]
                    )
                    {
                        rel material:binding:physics = </anymal_c/Physics/PhysicsMaterial>
                        uniform int mjc:group = 3
                        float newton:contactGap = 0
                        float physics:density = 1000
                    }

                    over "Cylinder_1" (
                        prepend apiSchemas = ["PhysicsCollisionAPI", "NewtonCollisionAPI", "MjcCollisionAPI", "PhysicsMassAPI", "MaterialBindingAPI"]
                    )
                    {
                        rel material:binding:physics = </anymal_c/Physics/PhysicsMaterial>
                        uniform int mjc:group = 3
                        float newton:contactGap = 0
                        float physics:density = 1000
                    }

                    def PhysicsRevoluteJoint "RF_HFE" (
                        prepend apiSchemas = ["MjcJointAPI"]
                    )
                    {
                        uniform double mjc:damping = 1
                        uniform double mjc:frictionloss = 0.1
                        uniform token physics:axis = "X"
                        rel physics:body0 = </anymal_c/Geometry/base/RF_HIP>
                        rel physics:body1 = </anymal_c/Geometry/base/RF_HIP/RF_THIGH>
                        point3f physics:localPos0 = (0.0599, 0.0725816, -0.041905)
                        point3f physics:localPos1 = (0, 0, 0)
                        quatf physics:localRot0 = (-0.68301266, 0.1830129, 0.18301292, 0.68301266)
                        quatf physics:localRot1 = (0, 0, -1, 0)
                        float physics:lowerLimit = -540.0001
                        float physics:upperLimit = 540.0001
                    }

                    def "RF_SHANK" (
                        prepend apiSchemas = ["PhysicsRigidBodyAPI", "PhysicsMassAPI"]
                    )
                    {
                        point3f physics:centerOfMass = (0.005462, 0.0612528, -0.0806598)
                        float3 physics:diagonalInertia = (0.0101637, 0.00923838, 0.00111927)
                        float physics:mass = 0.58842
                        quatf physics:principalAxes = (0.992934, 0.115904, -0.00105487, 0.0254421)

                        over "Cylinder" (
                            prepend apiSchemas = ["PhysicsCollisionAPI", "NewtonCollisionAPI", "MjcCollisionAPI", "PhysicsMassAPI", "MaterialBindingAPI"]
                        )
                        {
                            rel material:binding:physics = </anymal_c/Physics/PhysicsMaterial>
                            uniform int mjc:group = 3
                            float newton:contactGap = 0
                            float physics:density = 1000
                        }

                        over "Box" (
                            prepend apiSchemas = ["PhysicsCollisionAPI", "NewtonCollisionAPI", "MjcCollisionAPI", "PhysicsMassAPI", "MaterialBindingAPI"]
                        )
                        {
                            rel material:binding:physics = </anymal_c/Physics/PhysicsMaterial>
                            uniform int mjc:group = 3
                            float newton:contactGap = 0
                            float physics:density = 1000
                        }

                        over "Cylinder_1" (
                            prepend apiSchemas = ["PhysicsCollisionAPI", "NewtonCollisionAPI", "MjcCollisionAPI", "PhysicsMassAPI", "MaterialBindingAPI"]
                        )
                        {
                            rel material:binding:physics = </anymal_c/Physics/PhysicsMaterial>
                            uniform int mjc:group = 3
                            float newton:contactGap = 0
                            float physics:density = 1000
                        }

                        over "Sphere" (
                            prepend apiSchemas = ["PhysicsCollisionAPI", "NewtonCollisionAPI", "MjcCollisionAPI", "PhysicsMassAPI", "MaterialBindingAPI"]
                        )
                        {
                            rel material:binding:physics = </anymal_c/Physics/PhysicsMaterial_1>
                            uniform int mjc:condim = 6
                            uniform int mjc:group = 3
                            uniform int mjc:priority = 1
                            uniform double[] mjc:solimp = [0.015, 1, 0.03, 0.5, 2]
                            float newton:contactGap = 0
                            float physics:density = 1000
                        }

                        def PhysicsRevoluteJoint "RF_KFE" (
                            prepend apiSchemas = ["MjcJointAPI"]
                        )
                        {
                            uniform double mjc:damping = 1
                            uniform double mjc:frictionloss = 0.1
                            uniform token physics:axis = "X"
                            rel physics:body0 = </anymal_c/Geometry/base/RF_HIP/RF_THIGH>
                            rel physics:body1 = </anymal_c/Geometry/base/RF_HIP/RF_THIGH/RF_SHANK>
                            point3f physics:localPos0 = (0.1003, -5.551115e-17, -0.285)
                            point3f physics:localPos1 = (0, 0, 0)
                            quatf physics:localRot0 = (-2.646978e-23, 0, -1, 0)
                            quatf physics:localRot1 = (0, 0, -1, 0)
                            float physics:lowerLimit = -540.0001
                            float physics:upperLimit = 540.0001
                        }
                    }
                }
            }

            def "LH_HIP" (
                prepend apiSchemas = ["PhysicsRigidBodyAPI", "PhysicsMassAPI"]
            )
            {
                point3f physics:centerOfMass = (0.0567633, 0.015294, -0.00829784)
                float3 physics:diagonalInertia = (0.00585928, 0.0049205, 0.00329064)
                float physics:mass = 2.781
                quatf physics:principalAxes = (0.13524, 0.679072, 0.127985, 0.710065)

                over "Cylinder" (
                    prepend apiSchemas = ["PhysicsCollisionAPI", "NewtonCollisionAPI", "MjcCollisionAPI", "PhysicsMassAPI", "MaterialBindingAPI"]
                )
                {
                    rel material:binding:physics = </anymal_c/Physics/PhysicsMaterial>
                    uniform int mjc:group = 3
                    float newton:contactGap = 0
                    float physics:density = 1000
                }

                def PhysicsRevoluteJoint "LH_HAA" (
                    prepend apiSchemas = ["MjcJointAPI"]
                )
                {
                    uniform double mjc:damping = 1
                    uniform double mjc:frictionloss = 0.1
                    uniform token physics:axis = "X"
                    rel physics:body0 = </anymal_c/Geometry/base>
                    rel physics:body1 = </anymal_c/Geometry/base/LH_HIP>
                    point3f physics:localPos0 = (-0.2999, 0.104, 0)
                    point3f physics:localPos1 = (0, 0, 0)
                    quatf physics:localRot0 = (-0.9659259, 0.25881898, 6.123234e-17, 1.2325952e-32)
                    quatf physics:localRot1 = (0, 0, -1, 0)
                    float physics:lowerLimit = -41.25296
                    float physics:upperLimit = 28.074932
                }

                def "LH_THIGH" (
                    prepend apiSchemas = ["PhysicsRigidBodyAPI", "PhysicsMassAPI"]
                )
                {
                    point3f physics:centerOfMass = (0.0308147, 0.0000464995, -0.245696)
                    float3 physics:diagonalInertia = (0.0302511, 0.0298933, 0.0041845)
                    float physics:mass = 3.071
                    quatf physics:principalAxes = (0.992775, -0.00512735, -0.0806685, 0.0886811)

                    over "Cylinder" (
                        prepend apiSchemas = ["PhysicsCollisionAPI", "NewtonCollisionAPI", "MjcCollisionAPI", "PhysicsMassAPI", "MaterialBindingAPI"]
                    )
                    {
                        rel material:binding:physics = </anymal_c/Physics/PhysicsMaterial>
                        uniform int mjc:group = 3
                        float newton:contactGap = 0
                        float physics:density = 1000
                    }

                    over "Box" (
                        prepend apiSchemas = ["PhysicsCollisionAPI", "NewtonCollisionAPI", "MjcCollisionAPI", "PhysicsMassAPI", "MaterialBindingAPI"]
                    )
                    {
                        rel material:binding:physics = </anymal_c/Physics/PhysicsMaterial>
                        uniform int mjc:group = 3
                        float newton:contactGap = 0
                        float physics:density = 1000
                    }

                    over "Cylinder_1" (
                        prepend apiSchemas = ["PhysicsCollisionAPI", "NewtonCollisionAPI", "MjcCollisionAPI", "PhysicsMassAPI", "MaterialBindingAPI"]
                    )
                    {
                        rel material:binding:physics = </anymal_c/Physics/PhysicsMaterial>
                        uniform int mjc:group = 3
                        float newton:contactGap = 0
                        float physics:density = 1000
                    }

                    def PhysicsRevoluteJoint "LH_HFE" (
                        prepend apiSchemas = ["MjcJointAPI"]
                    )
                    {
                        uniform double mjc:damping = 1
                        uniform double mjc:frictionloss = 0.1
                        uniform token physics:axis = "X"
                        rel physics:body0 = </anymal_c/Geometry/base/LH_HIP>
                        rel physics:body1 = </anymal_c/Geometry/base/LH_HIP/LH_THIGH>
                        point3f physics:localPos0 = (0.0599, 0.0725816, -0.041905)
                        point3f physics:localPos1 = (0, 0, 0)
                        quatf physics:localRot0 = (-0.18301292, -0.68301266, -0.68301266, 0.1830129)
                        quatf physics:localRot1 = (1, 0, 0, 0)
                        float physics:lowerLimit = -540.0001
                        float physics:upperLimit = 540.0001
                    }

                    def "LH_SHANK" (
                        prepend apiSchemas = ["PhysicsRigidBodyAPI", "PhysicsMassAPI"]
                    )
                    {
                        point3f physics:centerOfMass = (0.005462, 0.0612528, -0.0806598)
                        float3 physics:diagonalInertia = (0.0101637, 0.00923838, 0.00111927)
                        float physics:mass = 0.58842
                        quatf physics:principalAxes = (0.992934, 0.115904, -0.00105487, 0.0254421)

                        over "Cylinder" (
                            prepend apiSchemas = ["PhysicsCollisionAPI", "NewtonCollisionAPI", "MjcCollisionAPI", "PhysicsMassAPI", "MaterialBindingAPI"]
                        )
                        {
                            rel material:binding:physics = </anymal_c/Physics/PhysicsMaterial>
                            uniform int mjc:group = 3
                            float newton:contactGap = 0
                            float physics:density = 1000
                        }

                        over "Box" (
                            prepend apiSchemas = ["PhysicsCollisionAPI", "NewtonCollisionAPI", "MjcCollisionAPI", "PhysicsMassAPI", "MaterialBindingAPI"]
                        )
                        {
                            rel material:binding:physics = </anymal_c/Physics/PhysicsMaterial>
                            uniform int mjc:group = 3
                            float newton:contactGap = 0
                            float physics:density = 1000
                        }

                        over "Cylinder_1" (
                            prepend apiSchemas = ["PhysicsCollisionAPI", "NewtonCollisionAPI", "MjcCollisionAPI", "PhysicsMassAPI", "MaterialBindingAPI"]
                        )
                        {
                            rel material:binding:physics = </anymal_c/Physics/PhysicsMaterial>
                            uniform int mjc:group = 3
                            float newton:contactGap = 0
                            float physics:density = 1000
                        }

                        over "Sphere" (
                            prepend apiSchemas = ["PhysicsCollisionAPI", "NewtonCollisionAPI", "MjcCollisionAPI", "PhysicsMassAPI", "MaterialBindingAPI"]
                        )
                        {
                            rel material:binding:physics = </anymal_c/Physics/PhysicsMaterial_1>
                            uniform int mjc:condim = 6
                            uniform int mjc:group = 3
                            uniform int mjc:priority = 1
                            uniform double[] mjc:solimp = [0.015, 1, 0.03, 0.5, 2]
                            float newton:contactGap = 0
                            float physics:density = 1000
                        }

                        def PhysicsRevoluteJoint "LH_KFE" (
                            prepend apiSchemas = ["MjcJointAPI"]
                        )
                        {
                            uniform double mjc:damping = 1
                            uniform double mjc:frictionloss = 0.1
                            uniform token physics:axis = "X"
                            rel physics:body0 = </anymal_c/Geometry/base/LH_HIP/LH_THIGH>
                            rel physics:body1 = </anymal_c/Geometry/base/LH_HIP/LH_THIGH/LH_SHANK>
                            point3f physics:localPos0 = (0.1003, 5.551115e-17, -0.285)
                            point3f physics:localPos1 = (0, 0, 0)
                            quatf physics:localRot0 = (1, 0, 0, 0)
                            quatf physics:localRot1 = (1, 0, 0, 0)
                            float physics:lowerLimit = -540.0001
                            float physics:upperLimit = 540.0001
                        }
                    }
                }
            }

            def "RH_HIP" (
                prepend apiSchemas = ["PhysicsRigidBodyAPI", "PhysicsMassAPI"]
            )
            {
                point3f physics:centerOfMass = (0.0566606, -0.015294, -0.00829784)
                float3 physics:diagonalInertia = (0.00585729, 0.00491868, 0.00329081)
                float physics:mass = 2.781
                quatf physics:principalAxes = (-0.127978, 0.709783, -0.135278, 0.679359)

                over "Cylinder" (
                    prepend apiSchemas = ["PhysicsCollisionAPI", "NewtonCollisionAPI", "MjcCollisionAPI", "PhysicsMassAPI", "MaterialBindingAPI"]
                )
                {
                    rel material:binding:physics = </anymal_c/Physics/PhysicsMaterial>
                    uniform int mjc:group = 3
                    float newton:contactGap = 0
                    float physics:density = 1000
                }

                def PhysicsRevoluteJoint "RH_HAA" (
                    prepend apiSchemas = ["MjcJointAPI"]
                )
                {
                    uniform double mjc:damping = 1
                    uniform double mjc:frictionloss = 0.1
                    uniform token physics:axis = "X"
                    rel physics:body0 = </anymal_c/Geometry/base>
                    rel physics:body1 = </anymal_c/Geometry/base/RH_HIP>
                    point3f physics:localPos0 = (-0.2999, -0.104, 0)
                    point3f physics:localPos1 = (0, 0, 0)
                    quatf physics:localRot0 = (-0.9659259, -0.25881898, -1.5768437e-16, -1.1673463e-17)
                    quatf physics:localRot1 = (0, 0, -1, 0)
                    float physics:lowerLimit = -28.074932
                    float physics:upperLimit = 41.25296
                }

                def "RH_THIGH" (
                    prepend apiSchemas = ["PhysicsRigidBodyAPI", "PhysicsMassAPI"]
                )
                {
                    point3f physics:centerOfMass = (0.0308147, 0.0000464995, -0.245696)
                    float3 physics:diagonalInertia = (0.03025, 0.0298943, 0.00418465)
                    float physics:mass = 3.071
                    quatf physics:principalAxes = (0.993166, -0.00515309, -0.0806592, 0.0841972)

                    over "Cylinder" (
                        prepend apiSchemas = ["PhysicsCollisionAPI", "NewtonCollisionAPI", "MjcCollisionAPI", "PhysicsMassAPI", "MaterialBindingAPI"]
                    )
                    {
                        rel material:binding:physics = </anymal_c/Physics/PhysicsMaterial>
                        uniform int mjc:group = 3
                        float newton:contactGap = 0
                        float physics:density = 1000
                    }

                    over "Box" (
                        prepend apiSchemas = ["PhysicsCollisionAPI", "NewtonCollisionAPI", "MjcCollisionAPI", "PhysicsMassAPI", "MaterialBindingAPI"]
                    )
                    {
                        rel material:binding:physics = </anymal_c/Physics/PhysicsMaterial>
                        uniform int mjc:group = 3
                        float newton:contactGap = 0
                        float physics:density = 1000
                    }

                    over "Cylinder_1" (
                        prepend apiSchemas = ["PhysicsCollisionAPI", "NewtonCollisionAPI", "MjcCollisionAPI", "PhysicsMassAPI", "MaterialBindingAPI"]
                    )
                    {
                        rel material:binding:physics = </anymal_c/Physics/PhysicsMaterial>
                        uniform int mjc:group = 3
                        float newton:contactGap = 0
                        float physics:density = 1000
                    }

                    def PhysicsRevoluteJoint "RH_HFE" (
                        prepend apiSchemas = ["MjcJointAPI"]
                    )
                    {
                        uniform double mjc:damping = 1
                        uniform double mjc:frictionloss = 0.1
                        uniform token physics:axis = "X"
                        rel physics:body0 = </anymal_c/Geometry/base/RH_HIP>
                        rel physics:body1 = </anymal_c/Geometry/base/RH_HIP/RH_THIGH>
                        point3f physics:localPos0 = (0.0599, -0.0725816, -0.041905)
                        point3f physics:localPos1 = (0, 0, 0)
                        quatf physics:localRot0 = (0.68301266, 0.1830129, -0.18301292, 0.68301266)
                        quatf physics:localRot1 = (0, 0, -1, 0)
                        float physics:lowerLimit = -540.0001
                        float physics:upperLimit = 540.0001
                    }

                    def "RH_SHANK" (
                        prepend apiSchemas = ["PhysicsRigidBodyAPI", "PhysicsMassAPI"]
                    )
                    {
                        point3f physics:centerOfMass = (0.005462, -0.0612528, -0.0806598)
                        float3 physics:diagonalInertia = (0.0101637, 0.00923838, 0.00111927)
                        float physics:mass = 0.58842
                        quatf physics:principalAxes = (0.992934, -0.115904, -0.00105487, -0.0254421)

                        over "Cylinder" (
                            prepend apiSchemas = ["PhysicsCollisionAPI", "NewtonCollisionAPI", "MjcCollisionAPI", "PhysicsMassAPI", "MaterialBindingAPI"]
                        )
                        {
                            rel material:binding:physics = </anymal_c/Physics/PhysicsMaterial>
                            uniform int mjc:group = 3
                            float newton:contactGap = 0
                            float physics:density = 1000
                        }

                        over "Box" (
                            prepend apiSchemas = ["PhysicsCollisionAPI", "NewtonCollisionAPI", "MjcCollisionAPI", "PhysicsMassAPI", "MaterialBindingAPI"]
                        )
                        {
                            rel material:binding:physics = </anymal_c/Physics/PhysicsMaterial>
                            uniform int mjc:group = 3
                            float newton:contactGap = 0
                            float physics:density = 1000
                        }

                        over "Cylinder_1" (
                            prepend apiSchemas = ["PhysicsCollisionAPI", "NewtonCollisionAPI", "MjcCollisionAPI", "PhysicsMassAPI", "MaterialBindingAPI"]
                        )
                        {
                            rel material:binding:physics = </anymal_c/Physics/PhysicsMaterial>
                            uniform int mjc:group = 3
                            float newton:contactGap = 0
                            float physics:density = 1000
                        }

                        over "Sphere" (
                            prepend apiSchemas = ["PhysicsCollisionAPI", "NewtonCollisionAPI", "MjcCollisionAPI", "PhysicsMassAPI", "MaterialBindingAPI"]
                        )
                        {
                            rel material:binding:physics = </anymal_c/Physics/PhysicsMaterial_1>
                            uniform int mjc:condim = 6
                            uniform int mjc:group = 3
                            uniform int mjc:priority = 1
                            uniform double[] mjc:solimp = [0.015, 1, 0.03, 0.5, 2]
                            float newton:contactGap = 0
                            float physics:density = 1000
                        }

                        def PhysicsRevoluteJoint "RH_KFE" (
                            prepend apiSchemas = ["MjcJointAPI"]
                        )
                        {
                            uniform double mjc:damping = 1
                            uniform double mjc:frictionloss = 0.1
                            uniform token physics:axis = "X"
                            rel physics:body0 = </anymal_c/Geometry/base/RH_HIP/RH_THIGH>
                            rel physics:body1 = </anymal_c/Geometry/base/RH_HIP/RH_THIGH/RH_SHANK>
                            point3f physics:localPos0 = (0.1003, 0, -0.285)
                            point3f physics:localPos1 = (0, 0, 0)
                            quatf physics:localRot0 = (2.646978e-23, 0, -1, 0)
                            quatf physics:localRot1 = (0, 0, -1, 0)
                            float physics:lowerLimit = -540.0001
                            float physics:upperLimit = 540.0001
                        }
                    }
                }
            }
        }
    }
}

def PhysicsScene "PhysicsScene" (
    prepend apiSchemas = ["NewtonSceneAPI", "MjcSceneAPI"]
)
{
    uniform token mjc:compiler:angle = "radian"
    uniform token mjc:option:cone = "elliptic"
    uniform double mjc:option:impratio = 100
    uniform int newton:maxSolverIterations = 100
    uniform int newton:timeStepsPerSecond = 500
    vector3f physics:gravityDirection = (0, 0, -1)
    float physics:gravityMagnitude = 9.81
}

